Workbook
Name _2023: 估价结果明细表!#REF!
Name _2023年8月9日: 估价结果明细表!#REF!
Name 保险费: 测算表!$E$151
Name 保险费率: 测算表!$H$153
Name 报告出具日期: 测算表!$D$14
Name 报告出具日期大写: 测算表!$D$17
Name 报告有效期: 测算表!$F$14
Name 报告有效期大写: 测算表!$F$17
Name 比较法: 测算表!$A$3
Name 比较法测算结果单价: 测算表!$J$90
Name 比较法评估单价: 测算表!$B$3
Name 比较法评估总价: 测算表!$C$3
Name 比较法权重: 测算表!$D$3
Name 变现能力城建税计算方法: 测算表!$B$167
Name 变现能力地方税附加计算方法: 测算表!$B$169
Name 变现能力教育税附加计算方法: 测算表!$B$168
Name 变现能力其他费用计算方法: 测算表!$B$172
Name 变现能力所得税计算方法: 测算表!$B$171
Name 变现能力土地增值税计算方法: 测算表!$B$170
Name 变现能力增值税计算方法: 测算表!$B$166
Name 变现评估净值: 测算表!$E$175
Name 变现评估总价: 测算表!$E$164
Name 不存在或无法调查: [1]序列表!$I$2:$I$3
Name 层高: 测算表!$F$25
Name 层高修正系数: 测算表!$N$75
Name 朝向修正系数: 测算表!$N$72
Name 城建税变现价格分析: 测算表!$E$167
Name 城建税取费依据: 测算表!$C$167
Name 出租或占用状况: 测算表!$C$29
Name 处置时涉及到的各项税费合计: 测算表!$E$174
Name 道路状况修正系数: 测算表!$N$65
Name 地方税附加变现分析: 测算表!$E$169
Name 地方税附加取费依据: 测算表!$C$169
Name 地形地势: 测算表!$C$47
Name 地质: 测算表!$E$46
Name 方位: 测算表!$C$31
Name 房地产和家具总价大写: 测算表!$F$7
Name 房地产和家具总价小写: 测算表!$F$6
Name 房地产综合评估单价: 测算表!$E$3
Name 房地产综合评估总价: 测算表!$F$3
Name 房屋用途: 测算表!$D$22
Name 放大: 估价结果明细表!#REF!
Name 分摊土地使用权面积: 测算表!$B$23
Name 公共及基础设施状况: 测算表!$C$36
Name 公共设施完备度修正系数: 测算表!$N$67
Name 共有情况: 测算表!$D$21
Name 共有宗地面积: 测算表!$B$24
Name 估价: #REF!
Name 估价报告编号: 测算表!$B$13
Name 估价对象层高: 测算表!$C$75
Name 估价对象层高分: 测算表!$J$75
Name 估价对象朝向: 测算表!$C$72
Name 估价对象朝向分: 测算表!$J$72
Name 估价对象道路状况: 测算表!$C$65
Name 估价对象道路状况分: 测算表!$J$65
Name 估价对象公共设施完备度: 测算表!$C$67
Name 估价对象公共设施完备度分: 测算表!$J$67
Name 估价对象规划上限制: 测算表!$C$69
Name 估价对象规划上限制分: 测算表!$J$69
Name 估价对象基础设施完备度: 测算表!$C$66

Sheet 封面
A1: 一 | B1: 档案目录 | C1: 司法
C2: 其他
B3: 评估收费 | C3: 收费函
C4: 测算表

Sheet 司法归档目录
A1: 土地、房地产估价项目档案目录 （司法评估类） | F1: 返回
A2: ="项目名称：位于"&测算表!B20&"房地产的市场价值进行了评估鉴定。" -> 项目名称：位于渝中区长江一路79号15-1、15-6#房地产的市场价值进行了评估鉴定。
A3: ="报告编号："&测算表!B13 -> 报告编号：渝瑞达房评〔2024〕司字第212号
A4: 承办部门：评估部 | D4: 项目负责人：李中敬
A5: 序号 | B5: 工作底稿名称 | D5: 自查 （Y/N） | E5: 页 码
B6: 一、必备件
A7: 1 | B7: 估价结果报告（报告正文和报告附件）
A8: 2 | B8: 估价技术报告
A9: 3 | B9: 法院的《司法鉴定委托书》
A10: 4 | B10: 法院或当事人提供的权属资料（法院盖公章）、案情资料
A11: 5 | B11: 现场查勘记录（法院、当事人、估价师签字）、估价对象照片
A12: 6 | B12: 房地产、土地市调询价记录（房价，地价、租金合同）
A13: 7 | B13: 报告书送达签收记录
A14: 8 | B14: 估价机构内部三级复核表
A15: 9 | B15: 其他资料
B16: 二、主要件
A17: 10 | B17: 评估工作计划
A18: 11 | B18: 评估测算底稿
A19: 12 | B19: 与法院、当事人之间的往来函件
A20: 13 | B20: 出庭作证情况记录
A21: 14 | B21: 产权部门查询的权属资料复印件（权属情况不清楚时）
A22: 15 | B22: 公安部门出具的门牌号证明（实际门牌号与证件不符时）
A23: 16 | B23: 房屋、土地面积测绘报告（面积与实际不符时）
A24: 17 | B24: 法院、当事人的异议申请
A25: 18 | B25: 对异议申请的复议答复函
A26: 19 | B26: 其他资料
B27: 三、相关件
A28: 20 | B28: 评估工作日志
A29: 21 | B29: 未列入报告附件的相关权属资料
A30: 22 | B30: 未列入报告附件的相关文件、合同或协议
A31: 23 | B31: 未列入报告附件的专项说明
A32: 24 | B32: 未列入报告附件的对象照片
A33: 25 | B33: 其他资料
A34: 档案整理人： | C34: 立卷时间：
A35: 归档审查人： | C35: 审查时间：
A36: 档案管理人： | C36: 移交时间：

Sheet 档案目录
A1: 房地产评估项目档案目录 （一般评估项目不含征收、司法类） | F1: 返回
A2: 项目名称：位于渝中区陕西路9号A幢12-7号房地产的市场价值进行了评估鉴定。
A3: 报告编号：渝瑞达 [2012]房鉴字第066号
A4: 承办部门：评估部 | D4: 项目负责人：谢渝
A5: 序号 | B5: 工作底稿名称 | D5: 自查 （Y/N） | E5: 页 码
B6: 一、必备件
A7: 1 | B7: 估价结果报告（报告正文和报告附件）
A8: 2 | B8: 估价技术报告
A9: 3 | B9: 估价项目委托合同
A10: 4 | B10: 现场查勘记录
A11: 5 | B11: 市场信息调查记录
A12: 6 | B12: 估价机构内部三级复核表
A13: 7 | B13: 其他必备件
B14: 二、主要件
A15: 10 | B15: 估价项目评估委托书
A16: 11 | B16: 评估工作计划
A17: 12 | B17: 估价项目技术路线确定与价值测算表
A18: 13 | B18: 重大估价问题讨论记录表
A19: 14 | B19: 报告书签收记录
A20: 15 | B20: 估价项目中出具的正式函件（具有咨询性质）
A21: 16 | B21: 有关部门的备案及核准文件
A22: 17 | B22: 委托方及权利人提供资料清单
A23: 18 | B23: 其他相关件
B24: 三、相关件
A25: 20 | B25: 未列入报告附件的委托方相关信息资料
A26: 21 | B26: 未列入报告附件的相关权属资料
A27: 22 | B27: 未列入报告附件的与估价项目相关的文件、合同或协议
A28: 23 | B28: 未列入报告附件的专项说明
A29: 24 | B29: 未列入报告附件的估价对象照片
B30: 项目中的会议纪要及往来函件
A31: 25 | B31: 其他相关件
A32: 档案整理人： | C32: 立卷时间：
A33: 归档审查人： | C33: 审查时间：
A34: 档案管理人： | C34: 移交时间：

Sheet 收费涵
A1: 收费通知函 | H1: 返回
A2: =J3&"：" -> 重庆银行股份有限公司江北支行：
A3: =" 我公司接受"&测算表!B9&"委托，开展了对位于"&测算表!B20&"的房地产进行司法评估事宜（详见附件-《"&[0]!委托书&"》（委托书编号："&[0]!委托编号&"）复印件。并出具评估报告。根据《国家计委建设部关于房地产中介服务收费的通知》（计价格[1995]971号），本次评估收费按评估值差额定率累进方式，评估收费总金额为"&I7&"元（大写：人民币"&TEXT(INT(I7),"[DBNUM2]")&"元整），望及时支付。相关收费标准及计算如下：" -> 我公司接受重庆市渝北区人民法院委托，开展了对位于渝中区长江一路79号15-1、15-6#的房地产进行司法评估事宜（详见附件-《重庆市渝北区人民法院司法评估委托书》（委托书编号：（2024）渝北法委评字第858号）复印件。并出具评估报告。根据《国家计委建设部关于房地产中介服务收费的通知》（计价格[1995]971号），本次评估收费按评估值差额定率累进方式，评估收费总金额为8560元（大写：人民币捌仟伍佰陆拾元整），望及时支付。相关收费标准及计算如下： | I3: 申请方 | J3: 重庆银行股份有限公司江北支行
C4: 档次 | D4: 房地产价格总额 （万元） | E4: 累进计费率（‰） | I4: 房产评估收费计算
C5: 1 | D5: 100以下(含100) | E5: 5 | I5: 评估总价(万元) | J5: 正常 | K5: 九折 | L5: 八折 | M5: 七折 | N5: 六折 | O5: 五折 | Q5: 四折 | R5: 三折
C6: 2 | D6: 101以上至1,000 | E6: 2.5 | I6: =房地产综合评估总价 -> 242.45 | J6: =IF(I6<10000,IF(I6<100,I6*0.005*10000,IF(I6<1000,(5000+(I6-100)*0.0025*10000),IF(I6<2000,27500+(I6-1000)*10000*0.0015,IF(I6<5000,42500+10000*(I6-2000)*0.0008,IF(I6<8000,66500+10000*0.0004*(I6-5000),IF(I6<10000,78500+10000*0.0002*(I6-8000),1)))))),82500+(I6-10000)*1) -> 8561.25 | K6: =J6*0.9 -> 7705.125 | L6: =J6*0.8 -> 6849 | M6: =J6*0.7 -> 5992.875 | N6: =J6*0.6 -> 5136.75 | O6: =J6*0.5 -> 4280.625 | Q6: =J6*0.4 -> 3424.5 | R6: =J6*0.3 -> 2568.375
C7: 3 | D7: 1,001以上至2,000 | E7: 1.5 | I7: =ROUND(J6,-1) -> 8560
C8: 4 | D8: 2,001以上至5,000 | E8: 0.8
C9: 5 | D9: 5,001以上至8,000 | E9: 0.4
C10: 6 | D10: 8,001以上至10,000 | E10: 0.2
C11: 7 | D11: 10,000以上 | E11: 0.1
A12: 附我公司银行账户信息如下： 收费公司名称：重庆瑞达资产评估房地产土地估价有限公司 纳税人识别号（统一社会信用代码）：91500103747495363D 收费公司开户行：中国银行重庆渝州路支行 收费公司帐号：1088 8149 0265
A13: =" 附：《"&[0]!委托书&"》（委托书编号："&[0]!委托编号&"）复印件。" -> 附：《重庆市渝北区人民法院司法评估委托书》（委托书编号：（2024）渝北法委评字第858号）复印件。
A14: 重庆瑞达资产评估房地产土地估价有限公司
A15: =测算表!D14 -> 45523

Sheet 测算表
A1: 一、估价结果 | G1: 不管
A2: 评估方法 | B2: 评估单价 （元/㎡） | C2: 评估总价 （万元） | D2: 权重 | E2: 综合评估单价 （元/㎡） | F2: 综合评估总价 (万元） | G2: 必须手动输入
A3: 比较法 | B3: =J90 -> 9100 | C3: =ROUND(B3*D24/10000,2) -> 242.45 | D3: 1 | E3: =ROUND(B3*D3+B4*D4,-1) -> 9100 | F3: =ROUND(E3*建筑面积/10000,2) -> 242.45 | G3: 下拉选择输入
A4: 收益法 | B4: =G161 -> 4100 | C4: =ROUND(B4*建筑面积/10000,2) -> 109.24 | D4: =1-D3 -> 0
A5: 家具家电 | B5: / | C5: =ROUND(家具评估结果明细表!G3/10000,2) -> 1.26 | D5: / | E5: / | F5: =家具家电评估总价 -> 1.26
A6: 合计 | F6: =SUM(F3:F5) -> 243.71
A7: 房地产金额大写 | B7: =综合评估总价*10000 -> 2424500 | C7: 家具金额大写 | D7: =F5*10000 -> 12600 | E7: 房屋+家具大写 | F7: =房地产和家具总价小写*10000 -> 2437100
A8: 二、委托方基本信息
A9: 估价委托人 | B9: 重庆市渝北区人民法院 | C9: 联系人 | D9: 郑法官 | E9: 联系电话 | F9: 65439867
A10: 行为依据 | B10: 重庆市渝北区人民法院司法评估委托书 | C10: 委托编号 | D10: （2024）渝北法委评字第858号 | E10: 接受委托 | F10: 45482
A11: 照片文档位置 | B11: {=SUBSTITUTE(SUBSTITUTE(CELL("filename"), "\", "\\\\"), "[测算表.xlsx]测算表", "")} -> C:\\\\Users\\\\Administrator\\\\Desktop\\\\技术报告模板-最后专门用来写技术的，7000\\\\ | F11: =委托日期 -> 45482
A12: 三、报告基本信息
A13: 估价报告编号 | B13: 渝瑞达房评〔2024〕司字第212号
A14: 价值时点 | B14: 45518 | C14: 报告出具日期 | D14: 45523 | E14: 报告有效期 | F14: =报告出具日期+364 -> 45887
A15: 估价师1 | B15: 谢 渝 | C15: 注册号 | D15: =IF(估价师1名称="谢 渝","5020040059",IF(估价师1名称="闫凯旋","5020170017",IF(估价师1名称="韩 静","5020140014",IF(估价师1名称="洪 译","5020190014",IF(估价师1名称="蒋代平","5020210023"))))) -> 5020040059 | E15: 联系电话 | F15: 18623088071
A16: 估价师2 | B16: 闫凯旋 | C16: 注册号 | D16: =IF(B16="谢 渝","5020040059",IF(B16="闫凯旋","5020170017",IF(B16="韩 静","5020140014",IF(B16="洪 译","5020190014",IF(B16="蒋代平","5020210023"))))) -> 5020170017 | E16: 联系电话 | F16: 18580335533
A17: 价值时点大写 | B17: =价值时点 -> 45518 | C17: 报告出具日期大写 | D17: =报告出具日期 -> 45523 | E17: 报告有效期大写 | F17: =报告有效期 -> 45887
A18: 四、评估对象基本情况
A19: =IF(ISERR(FIND("不动",权属证书编号)),"房地产权证","不动产权证") -> 不动产权证 | B19: 渝（2020）渝中区不动产权第000855395号
A20: 坐落 | B20: 渝中区长江一路79号15-1、15-6#
A21: 权利人 | B21: 周忠华 | C21: 共有情况 | D21: 单独所有 | E21: 小区名称 | F21: E动力广场
A22: 土地用途 | B22: 城镇住宅用地 | C22: 房屋用途 | D22: 成套住宅 | E22: 建成时间 | F22: 2012
A23: 分摊土地使用权面积 | B23: 0 | C23: 套内面积 | D23: 167.21 | E23: 建筑物剩余使用年限 | F23: =ROUND(YEAR(价值时点)-建成时间,0) -> 12
A24: 共有宗地面积 | B24: 1213.3 | C24: 建筑面积 | D24: 266.43 | E24: 建筑物总楼层 | F24: 16
A25: 土地使用权类型 | B25: 出让 | C25: 建筑结构 | D25: 钢筋混凝土结构 | E25: 层高 | F25: 3
A26: 土地使用权终止日期 | B26: 55169 | C26: 所在楼层 | D26: 11 | E26: 外墙 | F26: 外墙漆
A27: 评估范围 | B27: 包含土地使用权、房屋所有权、部分房屋内可移动的家具家电、室内不可移动的装饰装修以及为房屋服务且不可分割或分割后影响其使用功能的设施设备，但不包含相应的债权债务等及其他财产或者权益
A28: 五、评估对象概况描述
A29: 1、权益状况： | B29: 出租或占用状况 | C29: 自用，无出租或占用情况
B30: 他项权利 | C30: =IF(E30="估价委托人介绍","根据估价委托人介绍,","根据估价委托人提供的《"&E30&"》记载,")&IF(F30="已设定抵押权利","估价对象已设定抵押并查封，本次估价未考虑抵押权因素和查封因素对估价结果产生影响",F30) -> 根据估价委托人介绍,估价对象已设定抵押并查封，本次估价未考虑抵押权因素和查封因素对估价结果产生影响 | E30: 估价委托人介绍 | F30: 已设定抵押权利
A31: 2、区位状况： | B31: 方位 | C31: 位于重庆大坪医院东侧 | D31: 距离 | E31: 距重庆大坪医院约1.5千米
B32: 朝向 | C32: 估价对象窗户朝东南 | D32: 临街状况 | E32: 长江一路
B33: 交通工具 | C33: 估价对象临长江一路，临轻轨1号线大坪站约1.5千米，临附近公交车站肖家湾·圣佑胃肠医院站，有29、411、416、421、819、873路公交车在此停靠，交通通达度好
B34: 停车状况 | C34: 估价对象周边有地面画线车位，周边有沿街占道临时停车位，停车方便
B35: 人文环境 | C35: 所在区域周边多为住宅楼，居民以一般职员为主，治安状况良好。相邻房地产以和泓江山国际、景泰利园、江屿朗廷等房地产为主，区域内居住适宜度较高
B36: 公共及基础设施状况 | C36: 估价对象周边有中国建设银行(渝中肖家湾支行)、中国邮政储蓄银行(长江二路邮政所)、渝中区解放小学、重庆大坪医院、复旦中学(竹园校区)、利民超市(上肖家塆)、邻里超市(上肖家湾店)等公共配套设施完善，区域内城市给排水、供电、路网等基础设施系统完善
A37: 3、建筑事物状况： | B37: 建筑规模 | C37: ="估价对象建筑面积为"&建筑面积&"平方米，套内面积为"&IF(OR(套内面积="",套内面积=0),"未记载",套内面积&"平方米") -> 估价对象建筑面积为266.43平方米，套内面积为167.21平方米
B38: 楼层 | C38: ="估价对象位于第28层；层高：约"&层高&"米；总层数：所在建筑物总楼层共"&建筑物总楼层&"层；所在建筑物地面总高约"&ROUND(建筑物总楼层*层高,0)&"米" -> 估价对象位于第28层；层高：约3米；总层数：所在建筑物总楼层共16层；所在建筑物地面总高约48米
B39: 设施设备 | C39: 给排水：接市政管网，消防设施：室外消火栓系统、烟感喷淋系统，通讯：程控交换机、光纤，供电：接市政供电网；电梯：配备电梯；通气状况：通气。配置的设施设备使用正常，性能完好
B40: 装饰装修 | C40: ="外墙为"&外墙&"，入户防盗门，室内客厅地面铺地砖，墙面刷漆，天棚吊顶，卧室地面铺木地板，墙面刷漆，天棚刷漆；厨卫：地面铺地砖，内墙瓷砖至顶，扣板吊顶" -> 外墙为外墙漆，入户防盗门，室内客厅地面铺地砖，墙面刷漆，天棚吊顶，卧室地面铺木地板，墙面刷漆，天棚刷漆；厨卫：地面铺地砖，内墙瓷砖至顶，扣板吊顶
...

Sheet 家具评估结果明细表
A1: 家具评估结果明细表
A2: ="坐落："&[0]!坐落 -> 坐落：渝中区长江一路79号15-1、15-6# | F2: 币种：人民币
A3: 序号 | B3: 名称 | C3: 单位 | D3: 数量 | E3: 评估价值（元） | F3: 备注 | G3: =E19 -> 12600 | H3: 重置成本（元） | I3: 综合成新率 | J3: 评估价（元）
A4: 1 | B4: 餐桌1 | C4: 套 | D4: 1 | E4: =J4 -> 680 | H4: 1700 | I4: 0.4 | J4: =ROUND(I4*H4,-1) -> 680
A5: 2 | B5: 茶几 | C5: 张 | D5: 1 | E5: =J5 -> 280 | H5: 700 | I5: 0.4 | J5: =ROUND(I5*H5,-1) -> 280
A6: 3 | B6: 沙发 | C6: 套 | D6: 1 | E6: =J6 -> 1200 | H6: 3000 | I6: 0.4 | J6: =ROUND(I6*H6,-1) -> 1200
A7: 4 | B7: 空调1 （柜） | C7: 台 | D7: 1 | E7: =J7 -> 2000 | H7: 8000 | I7: 0.25 | J7: =ROUND(I7*H7,-1) -> 2000
A8: 5 | B8: 餐桌2 | C8: 套 | D8: 1 | E8: =J8 -> 240 | H8: 600 | I8: 0.4 | J8: =ROUND(I8*H8,-1) -> 240
A9: 6 | B9: 冰箱 | C9: 台 | D9: 1 | E9: =J9 -> 760 | H9: 1900 | I9: 0.4 | J9: =ROUND(I9*H9,-1) -> 760
A10: 7 | B10: 床1 | C10: 张 | D10: 1 | E10: =J10 -> 840 | H10: 2100 | I10: 0.4 | J10: =ROUND(I10*H10,-1) -> 840
A11: 8 | B11: 空调2 （挂） | C11: 台 | D11: 1 | E11: =J11 -> 800 | H11: 2000 | I11: 0.4 | J11: =ROUND(I11*H11,-1) -> 800
A12: 9 | B12: 沙发 | C12: 张 | D12: 1 | E12: =J12 -> 320 | H12: 800 | I12: 0.4 | J12: =ROUND(I12*H12,-1) -> 320
A13: 10 | B13: 书桌 | C13: 个 | D13: 1 | E13: =J13 -> 200 | H13: 500 | I13: 0.4 | J13: =ROUND(I13*H13,-1) -> 200
A14: 11 | B14: 床2 | C14: 张 | D14: 1 | E14: =J14 -> 840 | H14: 2100 | I14: 0.4 | J14: =ROUND(I14*H14,-1) -> 840
A15: 12 | B15: 空调3 （挂） | C15: 台 | D15: 1 | E15: =J15 -> 800 | H15: 2000 | I15: 0.4 | J15: =ROUND(I15*H15,-1) -> 800
A16: 13 | B16: 办公桌 | C16: 张 | D16: 1 | E16: =J16 -> 520 | H16: 1300 | I16: 0.4 | J16: =ROUND(I16*H16,-1) -> 520
A17: 14 | B17: 柜子 | C17: 个 | D17: 1 | E17: =J17 -> 2400 | H17: =5*2*600 -> 6000 | I17: 0.4 | J17: =ROUND(I17*H17,-1) -> 2400
A18: 16 | B18: 衣柜2 | C18: 个 | D18: 1 | E18: =J18 -> 720 | H18: 2400 | I18: 0.3 | J18: =ROUND(I18*H18,-1) -> 720
A19: 合计 | E19: =SUM(E4:E18) -> 12600
A20: 重庆瑞达资产评估房地产土地估价有限公司
A21: 二〇二四年八月二十一日

Sheet 案例照片

Sheet 家具案例

Sheet 收益法（带有租金比较）
N1: 修正描述
A2: 收益价格计算表 | M2: 比较因素 估价对象及可比实例 | O2: 估价对象 | P2: 可比实例A | Q2: 可比实例B | R2: 可比实例C | T2: 比较因素 估价对象及可比实例 | V2: 权重 | W2: 估价对象 | X2: 可比实例A | Y2: 可比实例B | Z2: 可比实例C | AA2: 因素比较修正取值说明
A3: 一、年总收益 | M3: 名称 | O3: 住宅 | P3: 住宅 | Q3: 住宅 | R3: 住宅 | T3: 名称 | V3: —— | W3: =O3 -> 住宅 | X3: =P3 -> 住宅 | Y3: =Q3 -> 住宅 | Z3: =R3 -> 住宅
A4: 名称 | B4: 建筑面积 | C4: 月租金 | E4: 空置率（租金损失） | G4: 年租金收入(元) | J4: 1500 | M4: 坐落 | O4: =估价结果明细表!#REF! -> #REF! | P4: 合川区南办处望鹿街383号 | Q4: 合川区南办处望鹿街383号 | R4: 合川区南办处望鹿街383号 | T4: =M4 -> 坐落 | V4: —— | W4: =O4 -> #REF! | X4: =P4 -> 合川区南办处望鹿街383号 | Y4: =Q4 -> 合川区南办处望鹿街383号 | Z4: =R4 -> 合川区南办处望鹿街383号
A5: 代号 | B5: S1 | C5: S2 | E5: S3 | G5: S | M5: 租赁价格（元/平方米.月） | O5: 待求 | P5: 13 | Q5: 14 | R5: 14 | T5: =M5 -> 租赁价格（元/平方米.月） | V5: 1 | W5: =O5 -> 待求 | X5: =P5 -> 13 | Y5: =Q5 -> 14 | Z5: =R5 -> 14
A6: 计算公式 | B6: —— | C6: —— | E6: —— | G6: S=S1*S2*12*(1-S3) | M6: 交易时间 | O6: 价值时点 | P6: 43952 | Q6: 43953 | R6: 43954 | T6: 交易时间 | V6: 1 | W6: 100 | X6: 100 | Y6: 100 | Z6: 100
A7: 数值 | B7: 1 | C7: 14 | E7: 0.04 | G7: =B7*C7*12*(1-E7) -> 161.28 | M7: 交易情况 | O7: 正常 | P7: 正常 | Q7: 正常 | R7: 正常 | T7: 交易情况 | V7: 1 | W7: 100 | X7: 100 | Y7: 100 | Z7: 100
A8: 二、年总费用 | M8: 区位状况 | N8: 自然环境 | O8: 较好 | P8: 较好 | Q8: 较好 | R8: 较好 | T8: 区位状况调整 | U8: 自然环境 | V8: 0.1 | W8: 100 | X8: 100 | Y8: 100 | Z8: 100 | AA8: 以估价对象为100，三个可比实例与估价对象相似，因此修正系数均为100
A9: 名称 | B9: 税金 | C9: 管理费(1%-3%) | D9: 维修、保养费(1%) | E9: 保险费(0.2%) | F9: 年费用合计 | N9: 社会人文环境 | O9: 较好 | P9: 较好 | Q9: 较好 | R9: 较好 | U9: 社会人文环境 | V9: 0.05 | W9: 100 | X9: 100 | Y9: 100 | Z9: 100 | AA9: 以估价对象为100，三个可比实例与估价对象相似，因此修正系数均为100
A10: 代号 | B10: F1 | C10: F2 | D10: F3 | E10: F4 | F10: F | N10: 景观 | O10: 较好 | P10: 较好 | Q10: 较好 | R10: 较好 | U10: 景观 | V10: 0.1 | W10: 100 | X10: 100 | Y10: 100 | Z10: 100 | AA10: 以估价对象为100，三个可比实例与估价对象相似，因此修正系数均为100
A11: 计算公式 | B11: F1=S/(1+0.05)*0.176 | C11: F2=S*1% | D11: F3=建安*1% | E11: F4=建安*0.2% | F11: F=F1+F2+F3+F4 | N11: 距区域商业中心的距离 | O11: 距合川商业中心约1公里 | P11: 距合川商业中心约1公里 | Q11: 距合川商业中心约1公里 | R11: 距合川商业中心约1公里 | U11: 距区域商业中心的距离 | V11: 0.1 | W11: 100 | X11: 100 | Y11: 100 | Z11: 100 | AA11: 以估价对象为100，三个可比实例与估价对象相似，因此修正系数均为100
A12: 数值 | B12: =G7/(1+0.05)*0.176 -> 27.0336 | C12: =G7*0.01 -> 1.6128 | D12: =J4*0.01 -> 15 | E12: =J4*0.002 -> 3 | F12: =SUM(B12:E12) -> 46.6464 | N12: 道路状况 | O12: 较好 | P12: 较好 | Q12: 较好 | R12: 较好 | U12: 道路状况 | V12: 0.1 | W12: 100 | X12: 100 | Y12: 100 | Z12: 100 | AA12: 以估价对象为100，三个可比实例与估价对象一致，因此修正系数均为100
A13: 三、年纯收益 | N13: 基础设施完备度 | O13: 齐备 | P13: 齐备 | Q13: 齐备 | R13: 齐备 | U13: 基础设施完备度 | V13: 0.1 | W13: 100 | X13: 100 | Y13: 100 | Z13: 100 | AA13: 以估价对象为100，三个可比实例与估价对象相似，因此修正系数均为100
A14: 名称 | B14: 年租金收入 | D14: 年费用合计 | F14: 年纯收入 | N14: 公共设施完备度 | O14: 齐备 | P14: 齐备 | Q14: 齐备 | R14: 齐备 | U14: 公共设施完备度 | V14: 0.1 | W14: 100 | X14: 100 | Y14: 100 | Z14: 100 | AA14: 以估价对象为100，三个可比实例与估价对象相似，因此修正系数均为100
A15: 代号 | B15: S | D15: F | F15: A | N15: 交通状况 | O15: 较好 | P15: 较好 | Q15: 较好 | R15: 较好 | U15: 交通状况 | V15: 0.1 | W15: 100 | X15: 100 | Y15: 100 | Z15: 100 | AA15: 以估价对象为100，三个可比实例与估价对象相似，因此修正系数均为100
A16: 数值 | B16: =G7 -> 161.28 | D16: =F12 -> 46.6464 | F16: =B16-D16 -> 114.6336 | N16: 规划上限制 | O16: 住宅 | P16: 住宅 | Q16: 住宅 | R16: 住宅 | U16: 规划上限制 | V16: 0.05 | W16: 100 | X16: 100 | Y16: 100 | Z16: 100 | AA16: 以估价对象为100，三个可比实例与估价对象一致，因此修正系数均为100
A17: 计算公式 | B17: C=S-F | N17: 楼层 | O17: 3 | P17: 7 | Q17: 5 | R17: 10 | U17: 楼层 | V17: 0.1 | W17: 100 | X17: 104 | Y17: 102 | Z17: 107 | AA17: 以估价对象为100，三个可比实例与估价对象一致，因此修正系数均为100
A18: 四、求取收益价格 | N18: 朝向 | O18: 朝西 | P18: 朝西 | Q18: 朝西 | R18: 朝西 | U18: 朝向 | V18: 0.1 | W18: 100 | X18: 100 | Y18: 100 | Z18: 100 | AA18: 以估价对象为100，三个可比实例与估价对象相朝向相同，因此修正系数均为100
A19: 名称 | B19: 租金增长率(3%-10%) | C19: 租金增长年数(5-10) | D19: 资本化率 | E19: 收益年限 | F19: 收益系数 | G19: 收益价格（元/㎡） | M19: 实物状况 | N19: 结 构 | O19: 钢混 | P19: 钢混 | Q19: 钢混 | R19: 钢混 | U19: 区位状况调整指数 | V19: 1 | W19: =ROUND($V$8*W8+$V$9*W9+$V$10*W10+$V$11*W11+$V$12*W12+$V$13*W13+$V$14*W14+$V$15*W15+$V$16*W16+$V$17*W17+$V$18*W18,1) -> 100 | X19: =ROUND($V$8*X8+$V$9*X9+$V$10*X10+$V$11*X11+$V$12*X12+$V$13*X13+$V$14*X14+$V$15*X15+$V$16*X16+$V$17*X17+$V$18*X18,1) -> 100.4 | Y19: =ROUND($V$8*Y8+$V$9*Y9+$V$10*Y10+$V$11*Y11+$V$12*Y12+$V$13*Y13+$V$14*Y14+$V$15*Y15+$V$16*Y16+$V$17*Y17+$V$18*Y18,1) -> 100.2 | Z19: =ROUND($V$8*Z8+$V$9*Z9+$V$10*Z10+$V$11*Z11+$V$12*Z12+$V$13*Z13+$V$14*Z14+$V$15*Z15+$V$16*Z16+$V$17*Z17+$V$18*Z18,1) -> 100.7 | AA19: ——
A20: 代号 | B20: g | C20: m | D20: r | E20: n | F20: X | G20: V | N20: 层高（米） | O20: 5.8 | P20: 5.8 | Q20: 5.8 | R20: 5.8 | T20: 实物状况调整 | U20: 结 构 | V20: 0.1 | W20: 100 | X20: 100 | Y20: 100 | Z20: 100 | AA20: 以估价对象为100，三个可比实例与估价对象一致，因此修正系数均为100
A21: 计算公式 | B21: —— | C21: —— | D21: r=1.5%（安全利率）+4%（风险调整值） | E21: 土地可用法定最高年限 | G21: p=A*X | N21: 外 观 | O21: 涂料 | P21: 涂料 | Q21: 涂料 | R21: 涂料 | U21: =N20 -> 层高（米） | V21: 0.1 | W21: 100 | X21: 100 | Y21: 100 | Z21: 100 | AA21: 以估价对象为100，三个可比实例与估价对象一致，因此修正系数均为100
A22: 数值 | B22: 0.1 | C22: 10 | D22: 0.055 | E22: =估价结果明细表!#REF! -> #REF! | F22: =ROUND(1/(D22-B22)*(1-((1+B22)/(1+D22))^C22)+(1+B22)^(C22-1)/D22*(1-1/(1+D22)^(E22-C22))/(1+D22)^C22,4) -> #REF! | G22: =ROUND(F16*F22,-2) -> #REF! | N22: 装饰装修 | O22: 中装 | P22: 中装 | Q22: 中装 | R22: 中装 | U22: 外 观 | V22: 0.1 | W22: 100 | X22: 100 | Y22: 100 | Z22: 100 | AA22: 以估价对象为100，三个可比实例与估价对象一致，因此修正系数均为100
N23: 通风采光 | O23: 通风采光较好 | P23: 通风采光较好 | Q23: 通风采光较好 | R23: 通风采光较好 | U23: 装饰装修 | V23: 0.2 | W23: 100 | X23: 100 | Y23: 100 | Z23: 100 | AA23: 以估价对象为100，三个可比实例与估价对象装修相似，因此修正系数均为100
C24: 2016年 | D24: 已使用3年，尚可使用57年 | N24: 空间布局 | O24: 合理 | P24: 合理 | Q24: 合理 | R24: 合理 | U24: 通风采光 | V24: 0.1 | W24: 100 | X24: 100 | Y24: 100 | Z24: 100 | AA24: 以估价对象为100，三个可比实例与估价对象通风采光相似，因此修正系数均为100
N25: 物业管理 | O25: 好 | P25: 好 | Q25: 好 | R25: 好 | U25: 空间布局 | V25: 0.1 | W25: 100 | X25: 100 | Y25: 100 | Z25: 100 | AA25: 以估价对象为100，三个可比实例与估价对象相似，因此修正系数均为100
N26: 面积（M2） | O26: =估价结果明细表!#REF! -> #REF! | P26: 88 | Q26: 90 | R26: 90 | U26: 物业管理 | V26: 0.1 | W26: 100 | X26: 100 | Y26: 100 | Z26: 100 | AA26: 以估价对象为100，三个可比实例与估价对象一致，因此修正系数均为100
N27: 新旧程度（年） | O27: 2008 | P27: 2008 | Q27: 2008 | R27: 2008 | U27: 面积（M2） | V27: 0.1 | W27: 100 | X27: 105 | Y27: 105 | Z27: 105 | AA27: 以估价对象为100，三个可比实例与估价对象相似，因此修正系数均为100
M28: 权益状况 | N28: 土地使用权类型 | O28: 划拨 | P28: 划拨 | Q28: 划拨 | R28: 划拨 | U28: 新旧程度（年） | V28: 0.1 | W28: 100 | X28: 100 | Y28: 100 | Z28: 100 | AA28: 以估价对象为100，三个可比实例与估价对象一致，因此修正系数均为100
N29: 土地使用权剩余使用年期（年） | O29: - | P29: 与估价对像相似 | Q29: 与估价对像相似 | R29: 与估价对像相似 | U29: 实物状况调整指数 | V29: =SUM(V20:V28) -> 1 | W29: =ROUND($V$20*W20+$V$21*W21+$V$22*W22+$V$23*W23+$V$24*W24+$V$25*W25+$V$26*W26+$V$27*W27+$V$28*W28,1) -> 100 | X29: =ROUND($V$20*X20+$V$21*X21+$V$22*X22+$V$23*X23+$V$24*X24+$V$25*X25+$V$26*X26+$V$27*X27+$V$28*X28,1) -> 100.5 | Y29: =ROUND($V$20*Y20+$V$21*Y21+$V$22*Y22+$V$23*Y23+$V$24*Y24+$V$25*Y25+$V$26*Y26+$V$27*Y27+$V$28*Y28,1) -> 100.5 | Z29: =ROUND($V$20*Z20+$V$21*Z21+$V$22*Z22+$V$23*Z23+$V$24*Z24+$V$25*Z25+$V$26*Z26+$V$27*Z27+$V$28*Z28,1) -> 100.5 | AA29: ——
N30: 有无租约限制 | O30: 无 | P30: 有租约,租期较短 | Q30: 有租约,租期较短 | R30: 有租约,租金客观 | T30: 权益状况调整 | U30: 土地使用权类型 | V30: 0.3 | W30: 100 | X30: 100 | Y30: 100 | Z30: 100 | AA30: 以估价对象为100，三个可比实例与估价对象一致，因此修正系数均为100
N31: 有无抵押他项权 | O31: 设定为无 | P31: 无 | Q31: 无 | R31: 无 | U31: 土地使用权剩余使用年期 | V31: 0.3 | W31: 100 | X31: 100 | Y31: 100 | Z31: 100 | AA31: 以估价对象为100，三个可比实例与估价对象相似，因此修正系数均为100
B32: 比较项目 | C32: 可比实例一 | D32: 可比实例二 | E32: 可比实例三 | P32: =P5*P26 -> 1144 | Q32: =Q5*Q26 -> 1260 | R32: =R5*R26 -> 1260 | U32: 有无租约限制 | V32: 0.2 | W32: 100 | X32: 100 | Y32: 100 | Z32: 100 | AA32: 以估价对象为100，三个可比实例与估价对象一致，因此修正系数均为100
B33: 房地产坐落 | N33: 58561 | O33: 43472 | U33: 有无抵押他项权 | V33: 0.2 | W33: 100 | X33: 100 | Y33: 100 | Z33: 100 | AA33: 以估价对象为100，三个可比实例与估价对象一致，因此修正系数为100
B34: 地段 | S34: =P17 -> 7 | U34: 权益状况调整指数 | V34: =SUM(V30:V33) -> 1 | W34: 100 | X34: =ROUND((X30/W30*V30+X31/W31*V31+X32/W32*V32+X33/W33*V33)*100,2) -> 100 | Y34: =ROUND((Y30/W30*V30+Y31/W31*V31+Y32/W32*V32+Y33/W33*V33)*100,2) -> 100 | Z34: =ROUND((Z30/W30*V30+Z31/W31*V31+Z32/W32*V32+Z33/W33*V33)*100,2) -> 100 | AA34: —
B35: 建造年份（年） | C35: 2008 | D35: 2008 | E35: 2008 | J35: 1300 | T35: 比较价值 | V35: 待求 | X35: =ROUND(X5/X6/X7/X19/X29/X34*100^5,2) -> 12.88 | Y35: =ROUND(Y5/Y6/Y7/Y19/Y29/Y34*100^5,2) -> 13.9 | Z35: =ROUND(Z5/Z6/Z7/Z19/Z29/Z34*100^5,2) -> 13.83
B36: 土地性质 | C36: 出让 | D36: 出让 | E36: 出让 | T36: 评估单价 | V36: =ROUND((X35+Y35+Z35)/3,0) -> 14 | AA36: 2730
B37: 装修档次 | C37: 精装 | D37: 精装 | E37: 精装 | T37: 建筑面积 | V37: =O26 -> #REF!
B38: 所在层 | C38: 6 | D38: 10 | E38: 6 | T38: 装修单价（元/平方米） | V38: 0
B39: 租赁面积（M2） | C39: 88 | D39: 90 | E39: 92 | T39: 加上装修后单价 | V39: =V38+V36 -> 14
B40: 租赁期限（年） | C40: 1 | D40: 1 | E40: 1
...

Sheet 估价结果明细表
A1: 估价对象 | B1: =IF(ISERR(FIND("不动",B2)),"房地产权证","不动产权证") -> 房地产权证 | C1: 权利人 | D1: 坐落 | E1: 土地使用权类型 | F1: 土地使用权终止日期 | G1: 土地使用权面积(㎡) | H1: 共有宗地面积(㎡) | I1: 建筑结构 | J1: 房屋用途 | K1: 楼层 | L1: 建筑面积(㎡) | M1: 套内面积(㎡) | N1: 评估单价（元/㎡） | O1: 评估总价（万元） | P1: 价值时点 | Q1: 剩余使用年限（年）
B5: {=MID(CELL("filename"),FIND("[",CELL("filename"))+1,FIND("]",CELL("filename" ))-FIND("[",CELL("filename"))-1)} -> 测算表.xlsx
B6: {=CELL("filename")} -> C:\Users\Administrator\Desktop\技术报告模板-最后专门用来写技术的，7000\[测算表.xlsx]测算表
